WARNING  urllib3.connectionpool:connectionpool.py:812 Retrying (Retry(total=2, connect=None, read=None, redirect=None, status=None)) after connection broken by 'ConnectTimeoutError(<urllib3.connection.HTTPConnection object at 0x000002D778677220>, 'Connection to 192.168.0.108 timed out. (connect timeout=None)')': /wd/hub/session
WARNING  urllib3.connectionpool:connectionpool.py:812 Retrying (Retry(total=1, connect=None, read=None, redirect=None, status=None)) after connection broken by 'ConnectTimeoutError(<urllib3.connection.HTTPConnection object at 0x000002D778677580>, 'Connection to 192.168.0.108 timed out. (connect timeout=None)')': /wd/hub/session
WARNING  urllib3.connectionpool:connectionpool.py:812 Retrying (Retry(total=0, connect=None, read=None, redirect=None, status=None)) after connection broken by 'ConnectTimeoutError(<urllib3.connection.HTTPConnection object at 0x000002D7786776D0>, 'Connection to 192.168.0.108 timed out. (connect timeout=None)')': /wd/hub/session